<?xml version="1.0"?>
<!-- =================================================================================== -->
<!-- |    This document was autogenerated by xacro from
/home/ubuntu/ws_blue/src/blue/blue_demos/manipulator_systems/description/urdf/uvms.config.xacro | -->
<!-- |    EDITING THIS FILE BY HAND IS NOT RECOMMENDED                                 | -->
<!-- =================================================================================== -->
<robot name="uvms">
  <link name="mount_link" />
  <joint name="mount_joint"
         type="fixed">
    <origin rpy="0 0 0"
            xyz="0.13 -0.109 0.029" />
    <parent link="base_link" />
    <child link="mount_link" />
  </joint>
  <!-- add some additional floats to the vehicle to compensate for the manipulator -->
  <link name="float_link">
    <!-- Front left -->
    <collision>
      <origin rpy="0 0 0"
              xyz="0.11425 0.14375 0.08" />
      <geometry>
        <box size="0.2285 0.2875 0.015" />
      </geometry>
    </collision>
    <!-- Front right -->
    <collision>
      <origin rpy="0 0 0"
              xyz="0.11425 -0.14375 0.08" />
      <geometry>
        <box size="0.2285 0.2875 0.035" />
      </geometry>
    </collision>
    <!-- Back right -->
    <collision>
      <origin rpy="0 0 0"
              xyz="-0.11425 -0.14375 0.08" />
      <geometry>
        <box size="0.2285 0.2875 0.005" />
      </geometry>
    </collision>
  </link>
  <joint name="float_joint"
         type="fixed">
    <origin rpy="0 0 0"
            xyz="0 0 0" />
    <parent link="base_link" />
    <child link="float_link" />
  </joint>
  <link name="base_footprint" />
  <link name="base_link">
    <inertial>
      <origin rpy="0 0 0"
              xyz="0.0 0.0 0.011" />
      <mass value="13.0" />
      <inertia ixx="0.26"
               ixy="0"
               ixz="0"
               iyy="0.23"
               iyz="0"
               izz="0.37" />
    </inertial>
    <visual>
      <geometry>
        <mesh filename="file:///home/ubuntu/ws_blue/install/blue_description/share/blue_description/meshes/bluerov2_heavy_reach/bluerov2_heavy_reach.dae"
              scale="0.025 0.025 0.025" />
      </geometry>
      <origin rpy="0 0 0"
              xyz="0 0 0" />
    </visual>
    <collision name="base_link_collision">
      <geometry>
        <box size="0.457 0.575 0.05" />
      </geometry>
      <origin rpy="0 0 0"
              xyz="0 0 0.06" />
    </collision>
  </link>
  <joint name="base_footprint_joint"
         type="fixed">
    <parent link="base_footprint" />
    <child link="base_link" />
  </joint>
  <link name="camera_link">
    <inertial>
      <mass value="0.0001" />
      <inertia ixx="0.0001"
               ixy="0"
               ixz="0"
               iyy="0.0001"
               iyz="0"
               izz="0.0001" />
    </inertial>
  </link>
  <link name="camera_mount_link">
    <inertial>
      <mass value="0.0001" />
      <inertia ixx="0.0001"
               ixy="0"
               ixz="0"
               iyy="0.0001"
               iyz="0"
               izz="0.0001" />
    </inertial>
  </link>
  <joint name="camera_mount_joint"
         type="fixed">
    <origin rpy="0 0 0"
            xyz="0.21 0 0.067" />
    <parent link="base_link" />
    <child link="camera_mount_link" />
  </joint>
  <joint name="camera_joint"
         type="fixed">
    <origin rpy="-1.571 0 -1.571"
            xyz="0 0 0" />
    <parent link="camera_mount_link" />
    <child link="camera_link" />
  </joint>
  <link name="thruster1">
    <inertial>
      <mass value="0.002" />
      <inertia ixx="0.001"
               ixy="0"
               ixz="0"
               iyy="0.001"
               iyz="0"
               izz="0.001" />
    </inertial>
    <visual>
      <geometry>
        <mesh filename="file:///home/ubuntu/ws_blue/install/blue_description/share/blue_description/meshes/t200/ccw_prop.dae" />
      </geometry>
      <origin rpy="-1.571 0 0"
              xyz="0 0 0" />
    </visual>
  </link>
  <joint name="thruster1_joint"
         type="continuous">
    <origin rpy="-1.571 1.571 -1.047"
            xyz="0.088 -0.102 -0.04" />
    <parent link="base_link" />
    <child link="thruster1" />
    <axis xyz="0 0 -1" />
    <limits effort="-1"
            velocity="-1" />
  </joint>
  <link name="thruster2">
    <inertial>
      <mass value="0.002" />
      <inertia ixx="0.001"
               ixy="0"
               ixz="0"
               iyy="0.001"
               iyz="0"
               izz="0.001" />
    </inertial>
    <visual>
      <geometry>
        <mesh filename="file:///home/ubuntu/ws_blue/install/blue_description/share/blue_description/meshes/t200/ccw_prop.dae" />
      </geometry>
      <origin rpy="-1.571 0 0"
              xyz="0 0 0" />
    </visual>
  </link>
  <joint name="thruster2_joint"
         type="continuous">
    <origin rpy="-1.571 1.571 -2.094"
            xyz="0.088 0.102 -0.04" />
    <parent link="base_link" />
    <child link="thruster2" />
    <axis xyz="0 0 -1" />
    <limits effort="-1"
            velocity="-1" />
  </joint>
  <link name="thruster3">
    <inertial>
      <mass value="0.002" />
      <inertia ixx="0.001"
               ixy="0"
               ixz="0"
               iyy="0.001"
               iyz="0"
               izz="0.001" />
    </inertial>
    <visual>
      <geometry>
        <mesh filename="file:///home/ubuntu/ws_blue/install/blue_description/share/blue_description/meshes/t200/cw_prop.dae" />
      </geometry>
      <origin rpy="-1.571 0 0"
              xyz="0 0 0" />
    </visual>
  </link>
  <joint name="thruster3_joint"
         type="continuous">
    <origin rpy="-1.571 1.571 1.047"
            xyz="-0.088 -0.102 -0.04" />
    <parent link="base_link" />
    <child link="thruster3" />
    <axis xyz="0 0 -1" />
    <limits effort="-1"
            velocity="-1" />
  </joint>
  <link name="thruster4">
    <inertial>
      <mass value="0.002" />
      <inertia ixx="0.001"
               ixy="0"
               ixz="0"
               iyy="0.001"
               iyz="0"
               izz="0.001" />
    </inertial>
    <visual>
      <geometry>
        <mesh filename="file:///home/ubuntu/ws_blue/install/blue_description/share/blue_description/meshes/t200/cw_prop.dae" />
      </geometry>
      <origin rpy="-1.571 0 0"
              xyz="0 0 0" />
    </visual>
  </link>
  <joint name="thruster4_joint"
         type="continuous">
    <origin rpy="-1.571 1.571 2.094"
            xyz="-0.088 0.102 -0.04" />
    <parent link="base_link" />
    <child link="thruster4" />
    <axis xyz="0 0 -1" />
    <limits effort="-1"
            velocity="-1" />
  </joint>
  <link name="thruster5">
    <inertial>
      <mass value="0.002" />
      <inertia ixx="0.001"
               ixy="0"
               ixz="0"
               iyy="0.001"
               iyz="0"
               izz="0.001" />
    </inertial>
    <visual>
      <geometry>
        <mesh filename="file:///home/ubuntu/ws_blue/install/blue_description/share/blue_description/meshes/t200/ccw_prop.dae" />
      </geometry>
      <origin rpy="-1.571 0 0"
              xyz="0 0 0" />
    </visual>
  </link>
  <joint name="thruster5_joint"
         type="continuous">
    <origin rpy="0 0 0"
            xyz="0.118 -0.215 0.064" />
    <parent link="base_link" />
    <child link="thruster5" />
    <axis xyz="0 0 -1" />
    <limits effort="-1"
            velocity="-1" />
  </joint>
  <link name="thruster6">
    <inertial>
      <mass value="0.002" />
      <inertia ixx="0.001"
               ixy="0"
               ixz="0"
               iyy="0.001"
               iyz="0"
               izz="0.001" />
    </inertial>
    <visual>
      <geometry>
        <mesh filename="file:///home/ubuntu/ws_blue/install/blue_description/share/blue_description/meshes/t200/cw_prop.dae" />
      </geometry>
      <origin rpy="-1.571 0 0"
              xyz="0 0 0" />
    </visual>
  </link>
  <joint name="thruster6_joint"
         type="continuous">
    <origin rpy="0 0 0"
            xyz="0.118 0.215 0.064" />
    <parent link="base_link" />
    <child link="thruster6" />
    <axis xyz="0 0 -1" />
    <limits effort="-1"
            velocity="-1" />
  </joint>
  <link name="thruster7">
    <inertial>
      <mass value="0.002" />
      <inertia ixx="0.001"
               ixy="0"
               ixz="0"
               iyy="0.001"
               iyz="0"
               izz="0.001" />
    </inertial>
    <visual>
      <geometry>
        <mesh filename="file:///home/ubuntu/ws_blue/install/blue_description/share/blue_description/meshes/t200/cw_prop.dae" />
      </geometry>
      <origin rpy="-1.571 0 0"
              xyz="0 0 0" />
    </visual>
  </link>
  <joint name="thruster7_joint"
         type="continuous">
    <origin rpy="0 0 0"
            xyz="-0.118 -0.215 0.064" />
    <parent link="base_link" />
    <child link="thruster7" />
    <axis xyz="0 0 -1" />
    <limits effort="-1"
            velocity="-1" />
  </joint>
  <link name="thruster8">
    <inertial>
      <mass value="0.002" />
      <inertia ixx="0.001"
               ixy="0"
               ixz="0"
               iyy="0.001"
               iyz="0"
               izz="0.001" />
    </inertial>
    <visual>
      <geometry>
        <mesh filename="file:///home/ubuntu/ws_blue/install/blue_description/share/blue_description/meshes/t200/ccw_prop.dae" />
      </geometry>
      <origin rpy="-1.571 0 0"
              xyz="0 0 0" />
    </visual>
  </link>
  <joint name="thruster8_joint"
         type="continuous">
    <origin rpy="0 0 0"
            xyz="-0.118 0.215 0.064" />
    <parent link="base_link" />
    <child link="thruster8" />
    <axis xyz="0 0 -1" />
    <limits effort="-1"
            velocity="-1" />
  </joint>
  <!-- links -->
  <!-- the distance from the mount center to the base_link is xyz="0.0374 0 0.0225" -->
  <link name="alpha_base_link">
    <visual>
      <geometry>
        <mesh filename="file:///home/ubuntu/ws_blue/install/reach_description/share/reach_description/meshes/alpha_5/RS1-1010.dae" />
      </geometry>
      <origin rpy="3.14159 0 0"
              xyz="0 0 0" />
    </visual>
    <collision>
      <geometry>
        <cylinder length="0.150"
                  radius="0.020" />
      </geometry>
      <origin rpy="0 1.57075 0"
              xyz="-0.055 0 0" />
    </collision>
    <inertial>
      <mass value="0.0001" />
      <inertia ixx="0.0001"
               ixy="0"
               ixz="0"
               iyy="0.0001"
               iyz="0"
               izz="0.0001" />
    </inertial>
  </link>
  <link name="alpha_m3_inline_link">
    <visual>
      <geometry>
        <mesh filename="file:///home/ubuntu/ws_blue/install/reach_description/share/reach_description/meshes/alpha_5/M3-INLINE.dae" />
      </geometry>
      <origin rpy="0 0 0"
              xyz="0 0 0" />
    </visual>
    <collision>
      <geometry>
        <cylinder length="0.150"
                  radius="0.020" />
      </geometry>
      <origin rpy="0 1.57075 0"
              xyz="-0.055 0 0" />
    </collision>
    <inertial>
      <mass value="0.341" />
      <origin xyz="-0.055 0 0" />
      <inertia ixx="0.0000682"
               ixy="0"
               ixz="0"
               iyy="0.000673"
               iyz="0"
               izz="0.000673" />
    </inertial>
  </link>
  <link name="alpha_m2_1_1_link">
    <visual>
      <geometry>
        <mesh filename="file:///home/ubuntu/ws_blue/install/reach_description/share/reach_description/meshes/alpha_5/M2-1-1.dae" />
      </geometry>
      <origin rpy="0 0 0"
              xyz="0 0 0" />
    </visual>
    <collision>
      <geometry>
        <cylinder length="0.033"
                  radius="0.020" />
      </geometry>
      <origin rpy="0 0 0"
              xyz="0 0 0.0165" />
    </collision>
    <inertial>
      <mass value="0.194" />
      <origin xyz="0 0 0.0165" />
      <inertia ixx="0.000037"
               ixy="0"
               ixz="0"
               iyy="0.000037"
               iyz="0"
               izz="0.0000388" />
    </inertial>
  </link>
  <link name="alpha_m2_link">
    <visual>
      <geometry>
        <mesh filename="file:///home/ubuntu/ws_blue/install/reach_description/share/reach_description/meshes/alpha_5/M2.dae" />
      </geometry>
      <origin rpy="0 0 0"
              xyz="0 0 0" />
    </visual>
    <collision>
      <geometry>
        <cylinder length="0.145"
                  radius="0.020" />
      </geometry>
      <origin rpy="0 0 0"
              xyz="-0.02 0 -0.0725" />
    </collision>
    <collision>
      <geometry>
        <cylinder length="0.040"
                  radius="0.020" />
      </geometry>
      <origin rpy="1.5707 0 0"
              xyz="0 0 0" />
    </collision>
    <collision>
      <geometry>
        <cylinder length="0.040"
                  radius="0.020" />
      </geometry>
      <origin rpy="1.5707 0 0"
              xyz="-0.040 0 -0.1453" />
    </collision>
    <inertial>
      <mass value="0.429" />
      <origin xyz="-0.02 0 -0.0725" />
      <inertia ixx="0.0008907"
               ixy="0"
               ixz="0"
               iyy="0.0008907"
               iyz="0"
               izz="0.0000858" />
    </inertial>
  </link>
  <link name="alpha_m2_1_3_link">
    <visual>
      <geometry>
        <mesh filename="file:///home/ubuntu/ws_blue/install/reach_description/share/reach_description/meshes/alpha_5/M2-1-3.dae" />
      </geometry>
      <origin rpy="0 0 0"
              xyz="0 0 0" />
    </visual>
    <collision>
      <geometry>
        <cylinder length="0.033"
                  radius="0.020" />
      </geometry>
      <origin rpy="0 0 0"
              xyz="0.02 0 0.0165" />
    </collision>
    <inertial>
      <mass value="0.115" />
      <origin xyz="0.02 0 0.0165" />
      <inertia ixx="0.0000219"
               ixy="0"
               ixz="0"
               iyy="0.0000219"
               iyz="0"
               izz="0.000023" />
    </inertial>
  </link>
  <link name="alpha_m1_link">
    <visual>
      <geometry>
        <mesh filename="file:///home/ubuntu/ws_blue/install/reach_description/share/reach_description/meshes/alpha_5/M1.dae" />
      </geometry>
      <origin rpy="0 -1.5707 0"
              xyz="0 0 0" />
    </visual>
    <collision>
      <geometry>
        <cylinder length="0.1"
                  radius="0.020" />
      </geometry>
      <origin rpy="0 0 0"
              xyz="0 0 0.05" />
    </collision>
    <inertial>
      <mass value="0.200" />
      <origin xyz="0 0 0.05" />
      <inertia ixx="0.0001867"
               ixy="0"
               ixz="0"
               iyy="0.0001867"
               iyz="0"
               izz="0.00004" />
    </inertial>
  </link>
  <link name="alpha_rs1_124_link">
    <visual>
      <geometry>
        <mesh filename="file:///home/ubuntu/ws_blue/install/reach_description/share/reach_description/meshes/alpha_5/RS1-124.dae" />
      </geometry>
      <origin rpy="0 -1.5707 0"
              xyz="0 0 0" />
    </visual>
    <collision>
      <geometry>
        <cylinder length="0.1"
                  radius="0.020" />
      </geometry>
      <origin rpy="0 0 0"
              xyz="0 0 0.05" />
    </collision>
    <inertial>
      <mass value="0.0001" />
      <inertia ixx="0.0001"
               ixy="0"
               ixz="0"
               iyy="0.0001"
               iyz="0"
               izz="0.0001" />
    </inertial>
  </link>
  <link name="alpha_push_rod">
    <visual>
      <origin rpy="0 0 0"
              xyz="0 0 0" />
      <geometry>
        <box size="0.001 0.001 0.001" />
      </geometry>
      <material name="transparent">
        <color rgba="0 0 0 0" />
      </material>
    </visual>
    <inertial>
      <mass value="0.0001" />
      <inertia ixx="0.0001"
               ixy="0"
               ixz="0"
               iyy="0.0001"
               iyz="0"
               izz="0.0001" />
    </inertial>
  </link>
  <!-- joints -->
  <joint name="alpha_base_joint"
         type="fixed">
    <origin rpy="0 0 0"
            xyz="0 0 0" />
    <parent link="mount_link" />
    <child link="alpha_base_link" />
  </joint>
  <joint name="alpha_mount_joint"
         type="fixed">
    <parent link="alpha_base_link" />
    <child link="alpha_m3_inline_link" />
    <origin rpy="0 0 0"
            xyz="0.124 0.004 0" />
  </joint>
  <joint name="alpha_axis_e"
         type="revolute">
    <parent link="alpha_m3_inline_link" />
    <child link="alpha_m2_1_1_link" />
    <origin xyz="0 0 0.014" />
    <axis xyz="0 0 1" />
    <limit effort="9.0"
           lower="0.0"
           upper="6.10"
           velocity="0.5" />
  </joint>
  <joint name="alpha_axis_d"
         type="revolute">
    <parent link="alpha_m2_1_1_link" />
    <child link="alpha_m2_link" />
    <origin xyz="-0.02 0 0.033" />
    <axis xyz="0 1 0" />
    <limit effort="9.0"
           lower="-3.49"
           upper="3.49"
           velocity="0.5" />
  </joint>
  <joint name="alpha_axis_c"
         type="revolute">
    <parent link="alpha_m2_link" />
    <child link="alpha_m2_1_3_link" />
    <origin rpy="0 0 3.14159"
            xyz="-0.04 0 -0.1453" />
    <axis xyz="0 1 0" />
    <limit effort="9.0"
           lower="0.0"
           upper="3.22"
           velocity="0.5" />
  </joint>
  <joint name="alpha_axis_b"
         type="revolute">
    <parent link="alpha_m2_1_3_link" />
    <child link="alpha_m1_link" />
    <origin rpy="0 0 2.09439"
            xyz="0.02 0 0.033" />
    <axis xyz="0 0 -1" />
    <limit effort="9.0"
           lower="0.0"
           upper="3.22"
           velocity="0.5" />
  </joint>
  <joint name="alpha_tcp_base_joint"
         type="fixed">
    <origin rpy="0 0 0"
            xyz="0 0 0.09975" />
    <parent link="alpha_m1_link" />
    <child link="alpha_rs1_124_link" />
  </joint>
  <joint name="alpha_axis_a"
         type="prismatic">
    <origin rpy="0 0 0"
            xyz="0 0 0.009" />
    <parent link="alpha_rs1_124_link" />
    <child link="alpha_push_rod" />
    <axis xyz="0 0 1" />
    <limit effort="10"
           lower="0"
           upper="0.015"
           velocity="10" />
  </joint>
  <!-- links -->
  <link name="alpha_rs1_130_link">
    <visual>
      <geometry>
        <mesh filename="file:///home/ubuntu/ws_blue/install/reach_description/share/reach_description/meshes/alpha_5/end_effectors/RS1-130.dae" />
      </geometry>
      <origin rpy="0 0 0"
              xyz="0 0 0" />
    </visual>
    <collision>
      <geometry>
        <box size="0.012 0.03 0.09" />
      </geometry>
      <origin rpy="0 0 0"
              xyz="0.0 -0.008 0.045" />
    </collision>
    <inertial>
      <mass value="0.055" />
      <origin rpy="0 0 0"
              xyz="0.0 -0.008 0.045" />
      <inertia ixx="0.00004125"
               ixy="0"
               ixz="0"
               iyy="0.000037785"
               iyz="0"
               izz="0.000004785" />
    </inertial>
  </link>
  <link name="alpha_rs1_139_link">
    <visual>
      <geometry>
        <mesh filename="file:///home/ubuntu/ws_blue/install/reach_description/share/reach_description/meshes/alpha_5/end_effectors/RS1-139.dae" />
      </geometry>
      <origin rpy="0 0 0"
              xyz="0 0 0" />
    </visual>
    <collision>
      <geometry>
        <box size="0.012 0.03 0.09" />
      </geometry>
      <origin rpy="0 0 0"
              xyz="0.0 0.008 0.045" />
    </collision>
    <inertial>
      <mass value="0.055" />
      <origin rpy="0 0 0"
              xyz="0.0 0.008 0.045" />
      <inertia ixx="0.00004125"
               ixy="0"
               ixz="0"
               iyy="0.000037785"
               iyz="0"
               izz="0.000004785" />
    </inertial>
  </link>
  <!-- define a tcp link for planning/control purposes -->
  <link name="alpha_tcp">
    <inertial>
      <mass value="0.0001" />
      <inertia ixx="0.0001"
               ixy="0"
               ixz="0"
               iyy="0.0001"
               iyz="0"
               izz="0.0001" />
    </inertial>
  </link>
  <!-- joints -->
  <joint name="alpha_rs1_130_joint"
         type="revolute">
    <origin rpy="0 0 0"
            xyz="0 0.0155 0.0069" />
    <parent link="alpha_rs1_124_link" />
    <child link="alpha_rs1_130_link" />
    <axis xyz="-1 0 0" />
    <limit effort="10"
           lower="0"
           upper="0.5"
           velocity="10" />
    <mimic joint="alpha_axis_a"
           multiplier="51"
           offset="0" />
  </joint>
  <joint name="alpha_rs1_139_joint"
         type="revolute">
    <origin rpy="0 0 0"
            xyz="0 -0.0155 0.0069" />
    <parent link="alpha_rs1_124_link" />
    <child link="alpha_rs1_139_link" />
    <axis xyz="1 0 0" />
    <limit effort="10"
           lower="0"
           upper="0.5"
           velocity="10" />
    <mimic joint="alpha_rs1_130_joint"
           multiplier="1"
           offset="0" />
  </joint>
  <joint name="alpha_tcp_joint"
         type="fixed">
    <origin rpy="0 -1.5707963267948966 0"
            xyz="0 0 0.04" />
    <parent link="alpha_rs1_124_link" />
    <child link="alpha_tcp" />
  </joint>
  <gazebo>
    <plugin filename="gz_ros2_control-system"
            name="gz_ros2_control::GazeboSimROS2ControlPlugin">
      <parameters>/home/ubuntu/ws_blue/src/blue/blue_demos/manipulator_systems/config/uvms_controllers.yaml</parameters>
    </plugin>
  </gazebo>
  <gazebo>
    <plugin filename="gz-sim-hydrodynamics-system"
            name="gz::sim::systems::Hydrodynamics">
      <link_name>base_footprint</link_name>
      <!-- Added mass -->
      <xDotU>0</xDotU>
      <yDotV>0</yDotV>
      <zDotW>0</zDotW>
      <kDotP>0</kDotP>
      <mDotQ>0</mDotQ>
      <nDotR>0</nDotR>
      <!-- First order stability derivative -->
      <xU>0</xU>
      <yV>0</yV>
      <zW>0</zW>
      <kP>0</kP>
      <mQ>0</mQ>
      <nR>0</nR>
      <!-- Second order stability derivative -->
      <xUabsU>-58.42</xUabsU>
      <yVabsV>-55.137</yVabsV>
      <zWabsW>-124.818</zWabsW>
      <kPabsP>-4.0</kPabsP>
      <mQabsQ>-4.0</mQabsQ>
      <nRabsR>-4.0</nRabsR>
    </plugin>
  </gazebo>
  <gazebo>
    <plugin filename="gz-sim-odometry-publisher-system"
            name="gz::sim::systems::OdometryPublisher">
      <odom_frame>map</odom_frame>
      <robot_base_frame>base_link</robot_base_frame>
      <dimensions>3</dimensions>
      <odom_publish_frequency>100</odom_publish_frequency>
    </plugin>
  </gazebo>
  <gazebo>
    <plugin filename="gz-sim-thruster-system"
            name="gz::sim::systems::Thruster">
      <namespace>uvms</namespace>
      <joint_name>thruster1_joint</joint_name>
      <thrust_coefficient>0.02</thrust_coefficient>
      <fluid_density>1000.0</fluid_density>
      <propeller_diameter>0.1</propeller_diameter>
      <velocity_control>true</velocity_control>
      <use_angvel_cmd>False</use_angvel_cmd>
    </plugin>
  </gazebo>
  <gazebo>
    <plugin filename="gz-sim-thruster-system"
            name="gz::sim::systems::Thruster">
      <namespace>uvms</namespace>
      <joint_name>thruster2_joint</joint_name>
      <thrust_coefficient>0.02</thrust_coefficient>
      <fluid_density>1000.0</fluid_density>
      <propeller_diameter>0.1</propeller_diameter>
      <velocity_control>true</velocity_control>
      <use_angvel_cmd>False</use_angvel_cmd>
    </plugin>
  </gazebo>
  <gazebo>
    <plugin filename="gz-sim-thruster-system"
            name="gz::sim::systems::Thruster">
      <namespace>uvms</namespace>
      <joint_name>thruster3_joint</joint_name>
      <!-- Reverse spin to balance torque -->
      <thrust_coefficient>-0.02</thrust_coefficient>
      <fluid_density>1000.0</fluid_density>
      <propeller_diameter>0.1</propeller_diameter>
      <velocity_control>true</velocity_control>
      <use_angvel_cmd>False</use_angvel_cmd>
    </plugin>
  </gazebo>
  <gazebo>
    <plugin filename="gz-sim-thruster-system"
            name="gz::sim::systems::Thruster">
      <namespace>uvms</namespace>
      <joint_name>thruster4_joint</joint_name>
      <!-- Reverse spin to balance torque -->
      <thrust_coefficient>-0.02</thrust_coefficient>
      <fluid_density>1000.0</fluid_density>
      <propeller_diameter>0.1</propeller_diameter>
      <velocity_control>true</velocity_control>
      <use_angvel_cmd>False</use_angvel_cmd>
    </plugin>
  </gazebo>
  <gazebo>
    <plugin filename="gz-sim-thruster-system"
            name="gz::sim::systems::Thruster">
      <namespace>uvms</namespace>
      <joint_name>thruster5_joint</joint_name>
      <thrust_coefficient>0.02</thrust_coefficient>
      <fluid_density>1000.0</fluid_density>
      <propeller_diameter>0.1</propeller_diameter>
      <velocity_control>true</velocity_control>
      <use_angvel_cmd>False</use_angvel_cmd>
    </plugin>
  </gazebo>
  <gazebo>
    <plugin filename="gz-sim-thruster-system"
            name="gz::sim::systems::Thruster">
      <namespace>uvms</namespace>
      <joint_name>thruster6_joint</joint_name>
      <!-- Reverse spin to balance torque -->
      <thrust_coefficient>-0.02</thrust_coefficient>
      <fluid_density>1000.0</fluid_density>
      <propeller_diameter>0.1</propeller_diameter>
      <velocity_control>true</velocity_control>
      <use_angvel_cmd>False</use_angvel_cmd>
    </plugin>
  </gazebo>
  <gazebo>
    <plugin filename="gz-sim-thruster-system"
            name="gz::sim::systems::Thruster">
      <namespace>uvms</namespace>
      <joint_name>thruster7_joint</joint_name>
      <!-- Reverse spin to balance torque -->
      <thrust_coefficient>-0.02</thrust_coefficient>
      <fluid_density>1000.0</fluid_density>
      <propeller_diameter>0.1</propeller_diameter>
      <velocity_control>true</velocity_control>
      <use_angvel_cmd>False</use_angvel_cmd>
    </plugin>
  </gazebo>
  <gazebo>
    <plugin filename="gz-sim-thruster-system"
            name="gz::sim::systems::Thruster">
      <namespace>uvms</namespace>
      <joint_name>thruster8_joint</joint_name>
      <thrust_coefficient>0.02</thrust_coefficient>
      <fluid_density>1000.0</fluid_density>
      <propeller_diameter>0.1</propeller_diameter>
      <velocity_control>true</velocity_control>
      <use_angvel_cmd>False</use_angvel_cmd>
    </plugin>
  </gazebo>
  <ros2_control name="UVMSControlSystem"
                type="system">
    <hardware>
      <plugin>gz_ros2_control/GazeboSimSystem</plugin>
    </hardware>
    <joint name="alpha_axis_a">
      <param name="device_id">1</param>
      <command_interface name="position">
        <param name="min">0</param>
        <param name="max">0.015</param>
      </command_interface>
      <command_interface name="velocity">
        <param name="min">-0.003</param>
        <param name="max">0.003</param>
      </command_interface>
      <command_interface name="effort" />
      <state_interface name="position">
        <param name="initial_value">0</param>
      </state_interface>
      <state_interface name="velocity">
        <param name="initial_value">0.0</param>
      </state_interface>
      <state_interface name="effort">
        <param name="initial_value">0.0</param>
      </state_interface>
    </joint>
    <joint name="alpha_axis_b">
      <param name="device_id">2</param>
      <command_interface name="position">
        <param name="min">0</param>
        <param name="max">3.22</param>
      </command_interface>
      <command_interface name="velocity">
        <param name="min">-0.8726646</param>
        <param name="max">0.8726646</param>
      </command_interface>
      <command_interface name="effort" />
      <state_interface name="position">
        <param name="initial_value">0</param>
      </state_interface>
      <state_interface name="velocity">
        <param name="initial_value">0.0</param>
      </state_interface>
      <state_interface name="effort">
        <param name="initial_value">0.0</param>
      </state_interface>
    </joint>
    <joint name="alpha_axis_c">
      <param name="device_id">3</param>
      <command_interface name="position">
        <param name="min">0</param>
        <param name="max">3.22</param>
      </command_interface>
      <command_interface name="velocity">
        <param name="min">-0.5235988</param>
        <param name="max">0.5235988</param>
      </command_interface>
      <command_interface name="effort" />
      <state_interface name="position">
        <param name="initial_value">0</param>
      </state_interface>
      <state_interface name="velocity">
        <param name="initial_value">0.0</param>
      </state_interface>
      <state_interface name="effort">
        <param name="initial_value">0.0</param>
      </state_interface>
    </joint>
    <joint name="alpha_axis_d">
      <param name="device_id">4</param>
      <command_interface name="position">
        <param name="min">0</param>
        <param name="max">3.49</param>
      </command_interface>
      <command_interface name="velocity">
        <param name="min">-0.5235988</param>
        <param name="max">0.5235988</param>
      </command_interface>
      <command_interface name="effort" />
      <state_interface name="position">
        <param name="initial_value">0</param>
      </state_interface>
      <state_interface name="velocity">
        <param name="initial_value">0.0</param>
      </state_interface>
      <state_interface name="effort">
        <param name="initial_value">0.0</param>
      </state_interface>
    </joint>
    <joint name="alpha_axis_e">
      <param name="device_id">5</param>
      <command_interface name="position">
        <param name="min">0</param>
        <param name="max">6.14</param>
      </command_interface>
      <command_interface name="velocity">
        <param name="min">-0.5235988</param>
        <param name="max">0.5235988</param>
      </command_interface>
      <command_interface name="effort" />
      <state_interface name="position">
        <param name="initial_value">3.14159</param>
      </state_interface>
      <state_interface name="velocity">
        <param name="initial_value">0.0</param>
      </state_interface>
      <state_interface name="effort">
        <param name="initial_value">0.0</param>
      </state_interface>
    </joint>
  </ros2_control>
  <hydrodynamics>
    <inertial>
      <mass value="16.61" />
      <inertia ixx="0.24"
               iyy="0.2"
               izz="0.4" />
      <center_of_gravity x="0.0"
                         y="0.0"
                         z="0.0" />
      <added_mass Kdp="-0.12"
                  Mdq="-0.12"
                  Ndr="-0.12"
                  Xdu="-12.7"
                  Ydv="-10.5"
                  Zdw="-14.57" />
    </inertial>
    <damping>
      <linear Kp="-0.31"
              Mq="-0.31"
              Nr="-0.31"
              Xu="-28.23"
              Yv="-18.29"
              Zw="-23.51" />
      <quadratic Kpp="-1.55"
                 Mqq="-1.55"
                 Nrr="-1.55"
                 Xuu="-93.47"
                 Yvv="-74.28"
                 Zww="-168.17" />
    </damping>
    <hydrostatics>
      <buoyancy value="159.91" />
      <center_of_buoyancy x="0.0"
                          y="0.0"
                          z="0.0" />
    </hydrostatics>
  </hydrodynamics>
</robot>
