<?xml version="1.0"?>
<!-- =================================================================================== -->
<!-- |    This document was autogenerated by xacro from
/home/ubuntu/ws_blue/src/blue/blue_demos/manipulator_systems/description/urdf/uvms.pinocchio.xacro | -->
<!-- |    EDITING THIS FILE BY HAND IS NOT RECOMMENDED                                 | -->
<!-- =================================================================================== -->
<robot name="uvms_pinocchio">
  <link name="mount_link" />
  <joint name="mount_joint"
         type="fixed">
    <origin rpy="0 0 0"
            xyz="0.13 -0.109 0.029" />
    <parent link="base_link" />
    <child link="mount_link" />
  </joint>
  <!-- add some additional floats to the vehicle to compensate for the manipulator -->
  <link name="float_link">
    <!-- Front left -->
    <collision>
      <origin rpy="0 0 0"
              xyz="0.11425 0.14375 0.08" />
      <geometry>
        <box size="0.2285 0.2875 0.015" />
      </geometry>
    </collision>
    <!-- Front right -->
    <collision>
      <origin rpy="0 0 0"
              xyz="0.11425 -0.14375 0.08" />
      <geometry>
        <box size="0.2285 0.2875 0.035" />
      </geometry>
    </collision>
    <!-- Back right -->
    <collision>
      <origin rpy="0 0 0"
              xyz="-0.11425 -0.14375 0.08" />
      <geometry>
        <box size="0.2285 0.2875 0.005" />
      </geometry>
    </collision>
  </link>
  <joint name="float_joint"
         type="fixed">
    <origin rpy="0 0 0"
            xyz="0 0 0" />
    <parent link="base_link" />
    <child link="float_link" />
  </joint>
  <link name="base_footprint" />
  <link name="base_link">
    <inertial>
      <origin rpy="0 0 0"
              xyz="0.0 0.0 0.011" />
      <mass value="13.0" />
      <inertia ixx="0.26"
               ixy="0"
               ixz="0"
               iyy="0.23"
               iyz="0"
               izz="0.37" />
    </inertial>
    <visual>
      <geometry>
        <mesh filename="file:///home/ubuntu/ws_blue/install/blue_description/share/blue_description/meshes/bluerov2_heavy_reach/bluerov2_heavy_reach.dae"
              scale="0.025 0.025 0.025" />
      </geometry>
      <origin rpy="0 0 0"
              xyz="0 0 0" />
    </visual>
    <collision name="base_link_collision">
      <geometry>
        <box size="0.457 0.575 0.05" />
      </geometry>
      <origin rpy="0 0 0"
              xyz="0 0 0.06" />
    </collision>
  </link>
  <joint name="base_footprint_joint"
         type="fixed">
    <parent link="base_footprint" />
    <child link="base_link" />
  </joint>
  <link name="camera_link">
    <inertial>
      <mass value="0.0001" />
      <inertia ixx="0.0001"
               ixy="0"
               ixz="0"
               iyy="0.0001"
               iyz="0"
               izz="0.0001" />
    </inertial>
  </link>
  <link name="camera_mount_link">
    <inertial>
      <mass value="0.0001" />
      <inertia ixx="0.0001"
               ixy="0"
               ixz="0"
               iyy="0.0001"
               iyz="0"
               izz="0.0001" />
    </inertial>
  </link>
  <joint name="camera_mount_joint"
         type="fixed">
    <origin rpy="0 0 0"
            xyz="0.21 0 0.067" />
    <parent link="base_link" />
    <child link="camera_mount_link" />
  </joint>
  <joint name="camera_joint"
         type="fixed">
    <origin rpy="-1.571 0 -1.571"
            xyz="0 0 0" />
    <parent link="camera_mount_link" />
    <child link="camera_link" />
  </joint>
  <!-- links -->
  <!-- the distance from the mount center to the base_link is xyz="0.0374 0 0.0225" -->
  <link name="alpha_base_link">
    <visual>
      <geometry>
        <mesh filename="file:///home/ubuntu/ws_blue/install/reach_description/share/reach_description/meshes/alpha_5/RS1-1010.dae" />
      </geometry>
      <origin rpy="3.14159 0 0"
              xyz="0 0 0" />
    </visual>
    <collision>
      <geometry>
        <cylinder length="0.150"
                  radius="0.020" />
      </geometry>
      <origin rpy="0 1.57075 0"
              xyz="-0.055 0 0" />
    </collision>
    <inertial>
      <mass value="0.0001" />
      <inertia ixx="0.0001"
               ixy="0"
               ixz="0"
               iyy="0.0001"
               iyz="0"
               izz="0.0001" />
    </inertial>
  </link>
  <link name="alpha_m3_inline_link">
    <visual>
      <geometry>
        <mesh filename="file:///home/ubuntu/ws_blue/install/reach_description/share/reach_description/meshes/alpha_5/M3-INLINE.dae" />
      </geometry>
      <origin rpy="0 0 0"
              xyz="0 0 0" />
    </visual>
    <collision>
      <geometry>
        <cylinder length="0.150"
                  radius="0.020" />
      </geometry>
      <origin rpy="0 1.57075 0"
              xyz="-0.055 0 0" />
    </collision>
    <inertial>
      <mass value="0.341" />
      <origin xyz="-0.055 0 0" />
      <inertia ixx="0.0000682"
               ixy="0"
               ixz="0"
               iyy="0.000673"
               iyz="0"
               izz="0.000673" />
    </inertial>
  </link>
  <link name="alpha_m2_1_1_link">
    <visual>
      <geometry>
        <mesh filename="file:///home/ubuntu/ws_blue/install/reach_description/share/reach_description/meshes/alpha_5/M2-1-1.dae" />
      </geometry>
      <origin rpy="0 0 0"
              xyz="0 0 0" />
    </visual>
    <collision>
      <geometry>
        <cylinder length="0.033"
                  radius="0.020" />
      </geometry>
      <origin rpy="0 0 0"
              xyz="0 0 0.0165" />
    </collision>
    <inertial>
      <mass value="0.194" />
      <origin xyz="0 0 0.0165" />
      <inertia ixx="0.000037"
               ixy="0"
               ixz="0"
               iyy="0.000037"
               iyz="0"
               izz="0.0000388" />
    </inertial>
  </link>
  <link name="alpha_m2_link">
    <visual>
      <geometry>
        <mesh filename="file:///home/ubuntu/ws_blue/install/reach_description/share/reach_description/meshes/alpha_5/M2.dae" />
      </geometry>
      <origin rpy="0 0 0"
              xyz="0 0 0" />
    </visual>
    <collision>
      <geometry>
        <cylinder length="0.145"
                  radius="0.020" />
      </geometry>
      <origin rpy="0 0 0"
              xyz="-0.02 0 -0.0725" />
    </collision>
    <collision>
      <geometry>
        <cylinder length="0.040"
                  radius="0.020" />
      </geometry>
      <origin rpy="1.5707 0 0"
              xyz="0 0 0" />
    </collision>
    <collision>
      <geometry>
        <cylinder length="0.040"
                  radius="0.020" />
      </geometry>
      <origin rpy="1.5707 0 0"
              xyz="-0.040 0 -0.1453" />
    </collision>
    <inertial>
      <mass value="0.429" />
      <origin xyz="-0.02 0 -0.0725" />
      <inertia ixx="0.0008907"
               ixy="0"
               ixz="0"
               iyy="0.0008907"
               iyz="0"
               izz="0.0000858" />
    </inertial>
  </link>
  <link name="alpha_m2_1_3_link">
    <visual>
      <geometry>
        <mesh filename="file:///home/ubuntu/ws_blue/install/reach_description/share/reach_description/meshes/alpha_5/M2-1-3.dae" />
      </geometry>
      <origin rpy="0 0 0"
              xyz="0 0 0" />
    </visual>
    <collision>
      <geometry>
        <cylinder length="0.033"
                  radius="0.020" />
      </geometry>
      <origin rpy="0 0 0"
              xyz="0.02 0 0.0165" />
    </collision>
    <inertial>
      <mass value="0.115" />
      <origin xyz="0.02 0 0.0165" />
      <inertia ixx="0.0000219"
               ixy="0"
               ixz="0"
               iyy="0.0000219"
               iyz="0"
               izz="0.000023" />
    </inertial>
  </link>
  <link name="alpha_m1_link">
    <visual>
      <geometry>
        <mesh filename="file:///home/ubuntu/ws_blue/install/reach_description/share/reach_description/meshes/alpha_5/M1.dae" />
      </geometry>
      <origin rpy="0 -1.5707 0"
              xyz="0 0 0" />
    </visual>
    <collision>
      <geometry>
        <cylinder length="0.1"
                  radius="0.020" />
      </geometry>
      <origin rpy="0 0 0"
              xyz="0 0 0.05" />
    </collision>
    <inertial>
      <mass value="0.200" />
      <origin xyz="0 0 0.05" />
      <inertia ixx="0.0001867"
               ixy="0"
               ixz="0"
               iyy="0.0001867"
               iyz="0"
               izz="0.00004" />
    </inertial>
  </link>
  <link name="alpha_rs1_124_link">
    <visual>
      <geometry>
        <mesh filename="file:///home/ubuntu/ws_blue/install/reach_description/share/reach_description/meshes/alpha_5/RS1-124.dae" />
      </geometry>
      <origin rpy="0 -1.5707 0"
              xyz="0 0 0" />
    </visual>
    <collision>
      <geometry>
        <cylinder length="0.1"
                  radius="0.020" />
      </geometry>
      <origin rpy="0 0 0"
              xyz="0 0 0.05" />
    </collision>
    <inertial>
      <mass value="0.0001" />
      <inertia ixx="0.0001"
               ixy="0"
               ixz="0"
               iyy="0.0001"
               iyz="0"
               izz="0.0001" />
    </inertial>
  </link>
  <link name="alpha_push_rod">
    <visual>
      <origin rpy="0 0 0"
              xyz="0 0 0" />
      <geometry>
        <box size="0.001 0.001 0.001" />
      </geometry>
      <material name="transparent">
        <color rgba="0 0 0 0" />
      </material>
    </visual>
    <inertial>
      <mass value="0.0001" />
      <inertia ixx="0.0001"
               ixy="0"
               ixz="0"
               iyy="0.0001"
               iyz="0"
               izz="0.0001" />
    </inertial>
  </link>
  <!-- joints -->
  <joint name="alpha_base_joint"
         type="fixed">
    <origin rpy="0 0 0"
            xyz="0 0 0" />
    <parent link="mount_link" />
    <child link="alpha_base_link" />
  </joint>
  <joint name="alpha_mount_joint"
         type="fixed">
    <parent link="alpha_base_link" />
    <child link="alpha_m3_inline_link" />
    <origin rpy="0 0 0"
            xyz="0.124 0.004 0" />
  </joint>
  <joint name="alpha_axis_e"
         type="revolute">
    <parent link="alpha_m3_inline_link" />
    <child link="alpha_m2_1_1_link" />
    <origin xyz="0 0 0.014" />
    <axis xyz="0 0 1" />
    <limit effort="9.0"
           lower="0.0"
           upper="6.10"
           velocity="0.5" />
  </joint>
  <joint name="alpha_axis_d"
         type="revolute">
    <parent link="alpha_m2_1_1_link" />
    <child link="alpha_m2_link" />
    <origin xyz="-0.02 0 0.033" />
    <axis xyz="0 1 0" />
    <limit effort="9.0"
           lower="-3.49"
           upper="3.49"
           velocity="0.5" />
  </joint>
  <joint name="alpha_axis_c"
         type="revolute">
    <parent link="alpha_m2_link" />
    <child link="alpha_m2_1_3_link" />
    <origin rpy="0 0 3.14159"
            xyz="-0.04 0 -0.1453" />
    <axis xyz="0 1 0" />
    <limit effort="9.0"
           lower="0.0"
           upper="3.22"
           velocity="0.5" />
  </joint>
  <joint name="alpha_axis_b"
         type="revolute">
    <parent link="alpha_m2_1_3_link" />
    <child link="alpha_m1_link" />
    <origin rpy="0 0 2.09439"
            xyz="0.02 0 0.033" />
    <axis xyz="0 0 -1" />
    <limit effort="9.0"
           lower="0.0"
           upper="3.22"
           velocity="0.5" />
  </joint>
  <joint name="alpha_tcp_base_joint"
         type="fixed">
    <origin rpy="0 0 0"
            xyz="0 0 0.09975" />
    <parent link="alpha_m1_link" />
    <child link="alpha_rs1_124_link" />
  </joint>
  <joint name="alpha_axis_a"
         type="prismatic">
    <origin rpy="0 0 0"
            xyz="0 0 0.009" />
    <parent link="alpha_rs1_124_link" />
    <child link="alpha_push_rod" />
    <axis xyz="0 0 1" />
    <limit effort="10"
           lower="0"
           upper="0.015"
           velocity="10" />
  </joint>
  <!-- links -->
  <link name="alpha_rs1_130_link">
    <visual>
      <geometry>
        <mesh filename="file:///home/ubuntu/ws_blue/install/reach_description/share/reach_description/meshes/alpha_5/end_effectors/RS1-130.dae" />
      </geometry>
      <origin rpy="0 0 0"
              xyz="0 0 0" />
    </visual>
    <collision>
      <geometry>
        <box size="0.012 0.03 0.09" />
      </geometry>
      <origin rpy="0 0 0"
              xyz="0.0 -0.008 0.045" />
    </collision>
    <inertial>
      <mass value="0.055" />
      <origin rpy="0 0 0"
              xyz="0.0 -0.008 0.045" />
      <inertia ixx="0.00004125"
               ixy="0"
               ixz="0"
               iyy="0.000037785"
               iyz="0"
               izz="0.000004785" />
    </inertial>
  </link>
  <link name="alpha_rs1_139_link">
    <visual>
      <geometry>
        <mesh filename="file:///home/ubuntu/ws_blue/install/reach_description/share/reach_description/meshes/alpha_5/end_effectors/RS1-139.dae" />
      </geometry>
      <origin rpy="0 0 0"
              xyz="0 0 0" />
    </visual>
    <collision>
      <geometry>
        <box size="0.012 0.03 0.09" />
      </geometry>
      <origin rpy="0 0 0"
              xyz="0.0 0.008 0.045" />
    </collision>
    <inertial>
      <mass value="0.055" />
      <origin rpy="0 0 0"
              xyz="0.0 0.008 0.045" />
      <inertia ixx="0.00004125"
               ixy="0"
               ixz="0"
               iyy="0.000037785"
               iyz="0"
               izz="0.000004785" />
    </inertial>
  </link>
  <!-- define a tcp link for planning/control purposes -->
  <link name="alpha_tcp">
    <inertial>
      <mass value="0.0001" />
      <inertia ixx="0.0001"
               ixy="0"
               ixz="0"
               iyy="0.0001"
               iyz="0"
               izz="0.0001" />
    </inertial>
  </link>
  <!-- joints -->
  <joint name="alpha_rs1_130_joint"
         type="revolute">
    <origin rpy="0 0 0"
            xyz="0 0.0155 0.0069" />
    <parent link="alpha_rs1_124_link" />
    <child link="alpha_rs1_130_link" />
    <axis xyz="-1 0 0" />
    <limit effort="10"
           lower="0"
           upper="0.5"
           velocity="10" />
    <mimic joint="alpha_axis_a"
           multiplier="51"
           offset="0" />
  </joint>
  <joint name="alpha_rs1_139_joint"
         type="revolute">
    <origin rpy="0 0 0"
            xyz="0 -0.0155 0.0069" />
    <parent link="alpha_rs1_124_link" />
    <child link="alpha_rs1_139_link" />
    <axis xyz="1 0 0" />
    <limit effort="10"
           lower="0"
           upper="0.5"
           velocity="10" />
    <mimic joint="alpha_rs1_130_joint"
           multiplier="1"
           offset="0" />
  </joint>
  <joint name="alpha_tcp_joint"
         type="fixed">
    <origin rpy="0 -1.5707963267948966 0"
            xyz="0 0 0.04" />
    <parent link="alpha_rs1_124_link" />
    <child link="alpha_tcp" />
  </joint>
</robot>
